Workbook
Name Chemical_Energy: Lookup!$O$3:$O$27
Name Chemical_Energy_Services: Lookup!$V$3:$V$7
Name Chemicals_and_Energy: 'Goods Data'!$E$2:$E$26
Name Chemicals_Energy: Lookup!$O$3:$O$27
Name Civil_and_Equipment: 'Goods Data'!$F$2:$F$26
Name Civil_and_Services: 'Service Data'!$E$2:$E$23
Name Corporate_Services: Lookup!$W$3:$W$27
Name dd_category: Lookup!$I$1:$K$1
Name Electrical_and_Equipment: 'Goods Data'!$G$2:$G$24
Name Electrical_and_Services: 'Service Data'!$F$2:$F$15
Name EngineeringProjectConstruction: Lookup!$Q$3:$Q$12
Name EPC_Services: Lookup!$X$3:$X$31
Name Equipment: Lookup!$R$3:$R$55
Name EquipmentServices: Lookup!$Y$3:$Y$6
Name FuelOils: Lookup!$O$3:$O$27
Name Geoscience: 'Service Data'!$G$2:$G$23
Name Geoscience_Services: Lookup!$Z$3:$Z$15
Name Health_and_Safety_and_and_and_Environment: 'Service Data'!$H$2:$H$8
Name Health_and_Safety_and_Equipment: 'Goods Data'!$H$2:$H$24
Name Instrumentation_and_Automation_and_Equipment: 'Goods Data'!$I$2:$I$23
Name Instrumentation_and_Automation_and_Services: 'Service Data'!$I$2:$I$13
Name IT_and_Services: 'Service Data'!$J$2:$J$11
Name IT_and_Telecom: 'Goods Data'!$J$2:$J$25
Name Linepipe: 'Goods Data'!$K$2:$K$11
Name Logistics: 'Service Data'!$K$2:$K$23
Name Made_In_Oman: 'Goods Data'!$B$2:$B$5
Name MadeinOman: Lookup!$E$2:$E$5
Name Mechanical_and_Services: 'Service Data'!$L$2:$L$15
Name Misc_Goods: Lookup!$P$3:$P$16
Name Misc_Services: Lookup!$AA$3:$AA$29
Name NonMade_In_Oman: 'Goods Data'!$C$2:$C$6
Name NotMadeinOman_ProcuredfromForeignRegisteredCompany: Lookup!$E$6
Name NotMadeinOman_ProcuredfromNationallyRegisteredCompany: Lookup!$E$2:$E$5
Name Other_and_Equipments: 'Goods Data'!$L$2:$L$12
Name Other_and_Services: 'Service Data'!$M$2:$M$15
Name Others: 'Goods Data'!$M$2:$M$2,'Service Data'!$N$2:$N$2
Name Pipeline_and_Construction: 'Service Data'!$O$2:$O$15
Name Project_and_Engineering_and_Services: 'Service Data'!$P$2:$P$20
Name Rotating_and_Equipment: 'Goods Data'!$N$2:$N$14
Name Services: Lookup!$P$14:$P$16
Name ServicesSourced_ForeignRegisteredCompany: Lookup!$K$2
Name ServicesSourced_NationalRegisteredCompany: Lookup!$E$2:$E$5
Name Static_and_MRO_and_Equipment: 'Goods Data'!$O$2:$O$34
Name Well_and_Services: 'Service Data'!$Q$2:$Q$30
Name Wells: Lookup!$S$3:$S$18
Name Wells_and_Equipment: 'Goods Data'!$P$2:$P$30
Name Wells_Services: Lookup!$AB$3:$AB$44

Sheet Tender Info
B1: Tender Information
B2: Tender Number | C2: TM-24-1339
B3: Contract Number
B4: Title | C4: Industrial Plant Cleaning Services
B5: Contract Duration (In Years) | C5: 6
B6: Currency | C6: USD
B7: Category | C7: Services
B8: Asset | C8: Oman LNG
B9: Investment Applicable | C9: FALSE
B10: Workforce Applicable | C10: TRUE
B11: Goods Applicable | C11: TRUE
B12: Services Applicable | C12: TRUE
B13: Indirect ICV Element Applicable | C13: TRUE
B14: Department
B15: Uploader Bidder Name

Sheet Guidelines
B1: Table A - Investment
B2: ICV Terminologies/Definitions
B4: “Capital Investment in Fixed Assets” means investments in fixed assets related to O&G industry in Oman, that are not charged directly to the client in whole or in part and related to the execution of this specific contract scope. This may include manufacturing facilities, service facilities, logistics-related facilities, repair and maintenance facilities, construction/refurbishment, research establishments etc. Excluded is any other new investment or existing that does not relate to contract scope.
B8: 1.Table A for Investment is split into 2 Tables as follows:
B9: a.Table A1: New/Furture fixed investment planned to be invested in Oman related to O&G sector that directly utilized in the execution/utilization to deliver this specific contract scope.
B11: b.Table A2: Existing investment previously invested in Oman that supports execution of the contract scope.
B12: For both Tables A1&A2, the following shall apply:
B13: 1.All the values in both tables above A1 and A2 shall be in USD currency.
B14: 2. Fixed Assets funded by Client company or others shall be EXCLUDED (i.e. Contractor must fund the investment)
B15: 3. Futrue fixed Assets funded by Client company and already regsitered with other O&G opreatros shall be REGISTERED as existing investment.
B16: 4. Fixed Assets substantially used (more than 50%) for purposes outside the scope of the Contract shall be excluded (e.g. new headquarters building allowing for future growth) shall be EXCLUDED
B18: E.g: Contract related to provision of technical equipment, the bidder shall list only investment in fixed assets such as manufacturing/repairing of that equipment but not investment required to support in delivering the scope of the contract such as Offices or delivery trucks.
... B137: SME - Small Medium Enterprise and below are the criteria for SME's
B138: Company Size | C138: Number of Employees | D138: Annual Turnover (R.O.)
B139: Micro | C139: 1 to 10 | D139: Less than 150,000
B140: Small | C140: 11 to 50 | D140: From 150,000 to Less Than 1,250,000
B141: Medium | C141: 51 to 150 | D141: From 1,250,000 to Less Than 5,000,000
B142: For more details to identify SME/LCC/SLCC/Large clasification please refer to Riyada or JSRS
B144: Table D - Services
B145: ICV Terminologies/Definitions
B147: Contractor shall complete Table D with the amount in USD paid for services that are to be sourced from Nationally-Registered Suppliers through Large,SLCC ,SME,LCC or Foreign Suppliers for utilisation in execution of the Contract.
B149: Contractor shall complete table with the amount paid for services that are to be sourced from Nationally-Registered Suppliers (NRS) or Foreign Suppliers for utilization in execution of the Contract.
B151: Contractor shall complete with the amount paid for services that are to be sourced DIRECT from Foreign Companies (FRS) for utilization in execution of the Contract.
B154: “Nationally-Registered Supplier (NRS)” means a supplier of goods and services that is a Company, subsidiary or branch incorporated under Omani law in Oman and/or registered to operate in Oman under a renewable license; and whose offices or facilities associated with producing manufactured or assembled goods or providing services to the Company are located in the Sultanate of Oman.
B158: “Foreign-Registered Supplier (FRS)” means a supplier of goods or services that is a company, subsidiary or branch not incorporated under Omani law in the Sultanate of Oman and/or registered to operate in the Sultanate of Oman under a renewable license.
B161: SLCC - Super Local Cimmunity Contractor
B162: LCC - Local Community Contractor
B163: Local Community Contractor shall mean a contractor that is registered in the Joint Supplier Registration System (JSRS) as a Company LCC. For further information on LCC(s),
B164: SME - Small Medium Enterprise and below are the criteria for SME's
B165: Company Size | C165: Number of Employees | D165: Annual Turnover (R.O.)
B166: Micro | C166: 1 to 10 | D166: Less than 150,000
B167: Small | C167: 11 to 50 | D167: From 150,000 to Less Than 1,250,000
B168: Medium | C168: 51 to 150 | D168: From 1,250,000 to Less Than 5,000,000
B169: For more details to identify SME/LCC/SLCC/Large clasification please refer to Riyada or JSRS

Sheet Table A Investment
B1: TM-24-1339 -: Investment : Fixed Investment related to execution of this specific Contract
B2: Key :
B3: To be completed by Contractor
B4: NOT to be completed by Contractor - auto/formula completion
B5: To Add new rows to the table, Select the entire last row of the table and drag it to create the number of new rows required.please DON'T insert a new row in the middle of the table.
B6: Total Future investment | F6: =SUMIF(B9:B143, "Future", F9:F941) -> 0
B7: Total Existing investment | F7: =SUMIF(B9:B143, "Existing", F9:F941) -> 0
B8: Investment Type | C8: Year of Investment | D8: Investment Category | E8: Summary Description of the investment (incl. location) | F8: Value (USD)

Sheet Table B Workforce - Contractor
B1: TM-24-1339 -: WORKFORCE related to execution of this specific contract duration with details of Main/Lead Contractor or Sub- Contractor.
B2: Full Contract Duration Workforce | C2: Existing Workforce Related to the Execution of this Specific Contract During Execution Period (Full Contract duration)
D3: Workforce Category | E3: Senior Management | H3: Professional | K3: Supervisory | N3: Skilled/Semi Skilled
E4: HD | F4: MH | G4: CP | H4: HD | I4: MH | J4: CP | K4: HD | L4: MH | M4: CP | N4: HD | O4: MH | P4: CP
C5: Contractor | D5: Omanis | E5: 0 | F5: =SUM(E30:E1000) -> 0 | G5: =SUMPRODUCT(E30:E1000,F30:F1000) -> 0 | H5: 0 | I5: =SUM(K30:K1000) -> 0 | J5: =SUMPRODUCT(K30:K1000,L30:L1000) -> 0 | K5: 0 | L5: =SUM(Q30:Q1000) -> 0 | M5: =SUMPRODUCT(Q30:Q1000,R30:R1000) -> 0 | N5: 0 | O5: =SUM(W30:W1000) -> 0 | P5: =SUMPRODUCT(W30:W1000,X30:X1000) -> 0
D6: Expatriate | E6: 0 | F6: =SUM(H30:H1000) -> 0 | G6: =SUMPRODUCT(H30:H1000,I30:I1000) -> 0 | H6: 0 | I6: =SUM(N30:N1000) -> 0 | J6: =SUMPRODUCT(N30:N1000,O30:O1000) -> 0 | K6: 0 | L6: =SUM(T30:T1000) -> 0 | M6: =SUMPRODUCT(T30:T1000,U30:U1000) -> 0 | N6: 0 | O6: =SUM(Z30:Z1000) -> 0 | P6: =SUMPRODUCT(Z30:Z1000,AA30:AA1000) -> 0
C8: Sub-Contractor | D8: Omanis | E8: 0 | F8: =SUM('Workforce - Subcontractor'!E6:E1000) -> 0 | G8: =SUMPRODUCT('Workforce - Subcontractor'!E6:E1000,'Workforce - Subcontractor'!F6:F1000) -> 0 | H8: 0 | I8: =SUM('Workforce - Subcontractor'!K6:K1000) -> 0 | J8: =SUMPRODUCT('Workforce - Subcontractor'!K6:K1000,'Workforce - Subcontractor'!L6:L1000) -> 0 | K8: 0 | L8: =SUM('Workforce - Subcontractor'!Q6:Q1000) -> 0 | M8: =SUMPRODUCT('Workforce - Subcontractor'!Q6:Q1000,'Workforce - Subcontractor'!R6:R1000) -> 0 | N8: 0 | O8: =SUM('Workforce - Subcontractor'!W6:W1000) -> 0 | P8: =SUMPRODUCT('Workforce - Subcontractor'!W6:W1000,'Workforce - Subcontractor'!X6:X1000) -> 0
D9: Expatriate | E9: 0 | F9: =SUM('Workforce - Subcontractor'!H6:H1000) -> 0 | G9: =SUMPRODUCT('Workforce - Subcontractor'!H6:H1000,'Workforce - Subcontractor'!I6:I1000) -> 0 | H9: 0 | I9: =SUM('Workforce - Subcontractor'!N6:N1000) -> 0 | J9: =SUMPRODUCT('Workforce - Subcontractor'!N6:N1000,'Workforce - Subcontractor'!O6:O1000) -> 0 | K9: 0 | L9: =SUM('Workforce - Subcontractor'!T6:T1000) -> 0 | M9: =SUMPRODUCT('Workforce - Subcontractor'!T6:T1000,'Workforce - Subcontractor'!U6:U1000) -> 0 | N9: 0 | O9: =SUM('Workforce - Subcontractor'!Z6:Z1000) -> 0 | P9: =SUMPRODUCT('Workforce - Subcontractor'!Z6:Z1000,'Workforce - Subcontractor'!AA6:AA1000) -> 0
C11: Total | D11: Omanis | E11: =E5+E8 -> 0 | F11: =F5+F8 -> 0 | G11: =SUM(G5+G8) -> 0 | H11: =H5+H8 -> 0 | I11: =I5+I8 -> 0 | J11: =SUM(J5+J8) -> 0 | K11: =K5+K8 -> 0 | L11: =L5+L8 -> 0 | M11: =SUM(M5+M8) -> 0 | N11: =N5+N8 -> 0 | O11: =O5+O8 -> 0 | P11: =SUM(P5+P8) -> 0
D12: Expatriate | E12: =E6+E9 -> 0 | F12: =F6+F9 -> 0 | G12: =SUM(G6+G9) -> 0 | H12: =H6+H9 -> 0 | I12: =I6+I9 -> 0 | J12: =SUM(J6+J9) -> 0 | K12: =K6+K9 -> 0 | L12: =L6+L9 -> 0 | M12: =SUM(M6+M9) -> 0 | N12: =N6+N9 -> 0 | O12: =O6+O9 -> 0 | P12: =SUM(P6+P9) -> 0
D13: % | E13: =IFERROR(E11/(E11+E12),0*100) -> 0 | F13: =IFERROR(F11/(F11+F12),0*100) -> 0 | G13: =IFERROR(G11/(G11+G12),0*100) -> 0 | H13: =IFERROR(H11/(H11+H12),0*100) -> 0 | I13: =IFERROR(I11/(I11+I12),0*100) -> 0 | J13: =IFERROR(J11/(J11+J12),0*100) -> 0 | K13: =IFERROR(K11/(K11+K12),0*100) -> 0 | L13: =IFERROR(L11/(L11+L12),0*100) -> 0 | ... P13: =IFERROR(P11/(P11+P12),0*100) -> 0
B16: During Bidding Duration | C16: Bidder Total Workforce | G16: Summary Consolidated | L16: Existing Employess | M16: Redeployment
C17: Total Headcount as per MOM | E17: Omani Percentages % | H17: HD | I17: MH | J17: CP | L17: 0 | M17: 0
C18: OM | D18: EXP | G18: Omanis | H18: =E11+H11+K11+N11 -> 0 | I18: =F11+I11+L11+O11 -> 0 | J18: =G11+J11+M11+P11 -> 0
C19: 0 | D19: 0 | E19: =IFERROR(C19/(C19+D19),0*100) -> 0 | G19: Expatriate | H19: =E12+H12+K12+N12 -> 0 | I19: =F12+I12+L12+O12 -> 0 | J19: =G12+J12+M12+P12 -> 0
G20: % | H20: =IFERROR(H18/(H18+H19),0*100) -> 0 | I20: =IFERROR(I18/(I18+I19),0*100) -> 0 | J20: =IFERROR(J18/(J18+J19),0*100) -> 0
B21: Key:
B22: To be completed by Contractor - Updates shall be based on contract duration period. For example, contract duartion for 2 years then bidders to update the table below for 2 years only.
B23: NOT to be completed by Contractor - auto/formula completion
B24: To Add new rows to the table, Select the entire last row of the table and drag it to create the number of new rows required.please DON'T insert a new row in the middle of the table.
B25: Workforce Related to the Execution of this Specific Contract During Execution Period (Yearly breakdown)
B26: HEADCOUNT AND MANHOURS PER CONTRACT YEAR DURING CONTRACT PERIOD - CONTRACTOR
B27: Year | C27: Period | D27: Senior Management | J27: Professional | P27: Supervisory | V27: Skilled/Semi | AB27: Total Quartely | AD27: Omani Percentages % | AE27: Total Yearly
D28: OM | G28: EXP | J28: OM | M28: EXP | P28: OM | S28: EXP | V28: OM | Y28: EXP
D29: HeadCount | E29: ManHours | F29: Compensation per Hour (USD) | G29: HeadCount | H29: ManHours | I29: Compensation per Hour (USD) | J29: HeadCount | K29: ManHours | L29: Compensation per Hour (USD) | M29: HeadCount | N29: ManHours | O29: Compensation per Hour (USD) | P29: HeadCount | Q29: ManHours | R29: Compensation per Hour (USD) | S29: HeadCount | T29: ManHours | U29: Compensation per Hour (USD) | V29: HeadCount | W29: ManHours | X29: Compensation per Hour (USD) | Y29: HeadCount | Z29: ManHours | AA29: Compensation per Hour (USD) | AB29: OM | AC29: EXP | AE29: OM
B30: Year 1 | C30: Q1 | D30: 0 | E30: 0 | F30: 0 | G30: 0 | H30: 0 | I30: 0 | J30: 0 | K30: 0 | L30: 0 | M30: 0 | N30: 0 | O30: 0 | P30: 0 | Q30: 0 | R30: 0 | S30: 0 | T30: 0 | U30: 0 | V30: 0 | W30: 0 | X30: 0 | Y30: 0 | Z30: 0 | AA30: 0 | AB30: =D30+J30+P30+V30 -> 0 | AC30: =G30+M30+S30+Y30 -> 0 | AD30: =IFERROR(AB30/SUM(AB30:AC30),0)*100 -> 0 | AE30: =SUM(D30:D33)+SUM(J30:J33)+SUM(P30:P33) +SUM(V30:V33) -> 0
B31: Year 1 | C31: Q2 | D31: 0 | E31: 0 | F31: 0 | G31: 0 | H31: 0 | I31: 0 | J31: 0 | K31: 0 | L31: 0 | M31: 0 | N31: 0 | O31: 0 | P31: 0 | Q31: 0 | R31: 0 | S31: 0 | T31: 0 | U31: 0 | V31: 0 | W31: 0 | X31: 0 | Y31: 0 | Z31: 0 | AA31: 0 | AB31: =D31+J31+P31+V31 -> 0 | AC31: =G31+M31+S31+Y31 -> 0 | AD31: =IFERROR(AB31/SUM(AB31:AC31),0)*100 -> 0
B32: Year 1 | C32: Q3 | D32: 0 | E32: 0 | F32: 0 | G32: 0 | H32: 0 | I32: 0 | J32: 0 | K32: 0 | L32: 0 | M32: 0 | N32: 0 | O32: 0 | P32: 0 | Q32: 0 | R32: 0 | S32: 0 | T32: 0 | U32: 0 | V32: 0 | W32: 0 | X32: 0 | Y32: 0 | Z32: 0 | AA32: 0 | AB32: =D32+J32+P32+V32 -> 0 | AC32: =G32+M32+S32+Y32 -> 0 | AD32: =IFERROR(AB32/SUM(AB32:AC32),0)*100 -> 0
B33: Year 1 | C33: Q4 | D33: 0 | E33: 0 | F33: 0 | G33: 0 | H33: 0 | I33: 0 | J33: 0 | K33: 0 | L33: 0 | M33: 0 | N33: 0 | O33: 0 | P33: 0 | Q33: 0 | R33: 0 | S33: 0 | T33: 0 | U33: 0 | V33: 0 | W33: 0 | X33: 0 | Y33: 0 | Z33: 0 | AA33: 0 | AB33: =D33+J33+P33+V33 -> 0 | AC33: =G33+M33+S33+Y33 -> 0 | AD33: =IFERROR(AB33/SUM(AB33:AC33),0)*100 -> 0
B34: Year 2 | C34: Q1 | D34: 0 | E34: 0 | F34: 0 | G34: 0 | H34: 0 | I34: 0 | J34: 0 | K34: 0 | L34: 0 | M34: 0 | N34: 0 | O34: 0 | P34: 0 | Q34: 0 | R34: 0 | S34: 0 | T34: 0 | U34: 0 | V34: 0 | W34: 0 | X34: 0 | Y34: 0 | Z34: 0 | AA34: 0 | AB34: =D34+J34+P34+V34 -> 0 | AC34: =G34+M34+S34+Y34 -> 0 | AD34: =IFERROR(AB34/SUM(AB34:AC34),0)*100 -> 0 | AE34: =SUM(D34:D37)+SUM(J34:J37)+SUM(P34:P37) +SUM(V34:V37) -> 0
B35: Year 2 | C35: Q2 | D35: 0 | E35: 0 | F35: 0 | G35: 0 | H35: 0 | I35: 0 | J35: 0 | K35: 0 | L35: 0 | M35: 0 | N35: 0 | O35: 0 | P35: 0 | Q35: 0 | R35: 0 | S35: 0 | T35: 0 | U35: 0 | V35: 0 | W35: 0 | X35: 0 | Y35: 0 | Z35: 0 | AA35: 0 | AB35: =D35+J35+P35+V35 -> 0 | AC35: =G35+M35+S35+Y35 -> 0 | AD35: =IFERROR(AB35/SUM(AB35:AC35),0)*100 -> 0
B36: Year 2 | C36: Q3 | D36: 0 | E36: 0 | F36: 0 | G36: 0 | H36: 0 | I36: 0 | J36: 0 | K36: 0 | L36: 0 | M36: 0 | N36: 0 | O36: 0 | P36: 0 | Q36: 0 | R36: 0 | S36: 0 | T36: 0 | U36: 0 | V36: 0 | W36: 0 | X36: 0 | Y36: 0 | Z36: 0 | AA36: 0 | AB36: =D36+J36+P36+V36 -> 0 | AC36: =G36+M36+S36+Y36 -> 0 | AD36: =IFERROR(AB36/SUM(AB36:AC36),0)*100 -> 0
B37: Year 2 | C37: Q4 | D37: 0 | E37: 0 | F37: 0 | G37: 0 | H37: 0 | I37: 0 | J37: 0 | K37: 0 | L37: 0 | M37: 0 | N37: 0 | O37: 0 | P37: 0 | Q37: 0 | R37: 0 | S37: 0 | T37: 0 | U37: 0 | V37: 0 | W37: 0 | X37: 0 | Y37: 0 | Z37: 0 | AA37: 0 | AB37: =D37+J37+P37+V37 -> 0 | AC37: =G37+M37+S37+Y37 -> 0 | AD37: =IFERROR(AB37/SUM(AB37:AC37),0)*100 -> 0
B38: Year 3 | C38: Q1 | D38: 0 | E38: 0 | F38: 0 | G38: 0 | H38: 0 | I38: 0 | J38: 0 | K38: 0 | L38: 0 | M38: 0 | N38: 0 | O38: 0 | P38: 0 | Q38: 0 | R38: 0 | S38: 0 | T38: 0 | U38: 0 | V38: 0 | W38: 0 | X38: 0 | Y38: 0 | Z38: 0 | AA38: 0 | AB38: =D38+J38+P38+V38 -> 0 | AC38: =G38+M38+S38+Y38 -> 0 | AD38: =IFERROR(AB38/SUM(AB38:AC38),0)*100 -> 0 | AE38: =SUM(D38:D41)+SUM(J38:J41)+SUM(P38:P41) +SUM(V38:V41) -> 0
B39: Year 3 | C39: Q2 | D39: 0 | E39: 0 | F39: 0 | G39: 0 | H39: 0 | I39: 0 | J39: 0 | K39: 0 | L39: 0 | M39: 0 | N39: 0 | O39: 0 | P39: 0 | Q39: 0 | R39: 0 | S39: 0 | T39: 0 | U39: 0 | V39: 0 | W39: 0 | X39: 0 | Y39: 0 | Z39: 0 | AA39: 0 | AB39: =D39+J39+P39+V39 -> 0 | AC39: =G39+M39+S39+Y39 -> 0 | AD39: =IFERROR(AB39/SUM(AB39:AC39),0)*100 -> 0
B40: Year 3 | C40: Q3 | D40: 0 | E40: 0 | F40: 0 | G40: 0 | H40: 0 | I40: 0 | J40: 0 | K40: 0 | L40: 0 | M40: 0 | N40: 0 | O40: 0 | P40: 0 | Q40: 0 | R40: 0 | S40: 0 | T40: 0 | U40: 0 | V40: 0 | W40: 0 | X40: 0 | Y40: 0 | Z40: 0 | AA40: 0 | AB40: =D40+J40+P40+V40 -> 0 | AC40: =G40+M40+S40+Y40 -> 0 | AD40: =IFERROR(AB40/SUM(AB40:AC40),0)*100 -> 0
B41: Year 3 | C41: Q4 | D41: 0 | E41: 0 | F41: 0 | G41: 0 | H41: 0 | I41: 0 | J41: 0 | K41: 0 | L41: 0 | M41: 0 | N41: 0 | O41: 0 | P41: 0 | Q41: 0 | R41: 0 | S41: 0 | T41: 0 | U41: 0 | V41: 0 | W41: 0 | X41: 0 | Y41: 0 | Z41: 0 | AA41: 0 | AB41: =D41+J41+P41+V41 -> 0 | AC41: =G41+M41+S41+Y41 -> 0 | AD41: =IFERROR(AB41/SUM(AB41:AC41),0)*100 -> 0
B42: Year 4 | C42: Q1 | D42: 0 | E42: 0 | F42: 0 | G42: 0 | H42: 0 | I42: 0 | J42: 0 | K42: 0 | L42: 0 | M42: 0 | N42: 0 | O42: 0 | P42: 0 | Q42: 0 | R42: 0 | S42: 0 | T42: 0 | U42: 0 | V42: 0 | W42: 0 | X42: 0 | Y42: 0 | Z42: 0 | AA42: 0 | AB42: =D42+J42+P42+V42 -> 0 | AC42: =G42+M42+S42+Y42 -> 0 | AD42: =IFERROR(AB42/SUM(AB42:AC42),0)*100 -> 0 | AE42: =SUM(D42:D45)+SUM(J42:J45)+SUM(P42:P45) +SUM(V42:V45) -> 0
B43: Year 4 | C43: Q2 | D43: 0 | E43: 0 | F43: 0 | G43: 0 | H43: 0 | I43: 0 | J43: 0 | K43: 0 | L43: 0 | M43: 0 | N43: 0 | O43: 0 | P43: 0 | Q43: 0 | R43: 0 | S43: 0 | T43: 0 | U43: 0 | V43: 0 | W43: 0 | X43: 0 | Y43: 0 | Z43: 0 | AA43: 0 | AB43: =D43+J43+P43+V43 -> 0 | AC43: =G43+M43+S43+Y43 -> 0 | AD43: =IFERROR(AB43/SUM(AB43:AC43),0)*100 -> 0
B44: Year 4 | C44: Q3 | D44: 0 | E44: 0 | F44: 0 | G44: 0 | H44: 0 | I44: 0 | J44: 0 | K44: 0 | L44: 0 | M44: 0 | N44: 0 | O44: 0 | P44: 0 | Q44: 0 | R44: 0 | S44: 0 | T44: 0 | U44: 0 | V44: 0 | W44: 0 | X44: 0 | Y44: 0 | Z44: 0 | AA44: 0 | AB44: =D44+J44+P44+V44 -> 0 | AC44: =G44+M44+S44+Y44 -> 0 | AD44: =IFERROR(AB44/SUM(AB44:AC44),0)*100 -> 0
...

Sheet Workforce - Subcontractor
B1: TM-24-1339 -: Workforce Related to the Execution of this Specific Contract During Execution Period (Yearly breakdown)
B2: HEADCOUNT AND MANHOURS PER CONTRACT YEAR DURING CONTRACT PERIOD - SUB CONTRACTOR
B3: Year | C3: Period | D3: Senior Management | J3: Professional | P3: Supervisory | V3: Skilled/Semi | AB3: Total Quartely | AD3: Omani Percentages % | AE3: Total Yearly
D4: OM | G4: EXP | J4: OM | M4: EXP | P4: OM | S4: EXP | V4: OM | Y4: EXP
D5: HeadCount | E5: ManHours | F5: Compensation per Hour (USD) | G5: HeadCount | H5: ManHours | I5: Compensation per Hour (USD) | J5: HeadCount | K5: ManHours | L5: Compensation per Hour (USD) | M5: HeadCount | N5: ManHours | O5: Compensation per Hour (USD) | P5: HeadCount | Q5: ManHours | R5: Compensation per Hour (USD) | S5: HeadCount | T5: ManHours | U5: Compensation per Hour (USD) | V5: HeadCount | W5: ManHours | X5: Compensation per Hour (USD) | Y5: HeadCount | Z5: ManHours | AA5: Compensation per Hour (USD) | AB5: OM | AC5: EXP | AE5: OM
B6: Year 1 | C6: Q1 | D6: 0 | E6: 0 | F6: 0 | G6: 0 | H6: 0 | I6: 0 | J6: 0 | K6: 0 | L6: 0 | M6: 0 | N6: 0 | O6: 0 | P6: 0 | Q6: 0 | R6: 0 | S6: 0 | T6: 0 | U6: 0 | V6: 0 | W6: 0 | X6: 0 | Y6: 0 | Z6: 0 | AA6: 0 | AB6: =D6+J6+P6+V6 -> 0 | AC6: =G6+M6+S6+Y6 -> 0 | AD6: =IFERROR(AB6/SUM(AB6:AC6),0)*100 -> 0 | AE6: =SUM(D6:D9)+SUM(J6:J9)+SUM(P6:P9) +SUM(V6:V9) -> 0
B7: Year 1 | C7: Q2 | D7: 0 | E7: 0 | F7: 0 | G7: 0 | H7: 0 | I7: 0 | J7: 0 | K7: 0 | L7: 0 | M7: 0 | N7: 0 | O7: 0 | P7: 0 | Q7: 0 | R7: 0 | S7: 0 | T7: 0 | U7: 0 | V7: 0 | W7: 0 | X7: 0 | Y7: 0 | Z7: 0 | AA7: 0 | AB7: =D7+J7+P7+V7 -> 0 | AC7: =G7+M7+S7+Y7 -> 0 | AD7: =IFERROR(AB7/SUM(AB7:AC7),0)*100 -> 0
B8: Year 1 | C8: Q3 | D8: 0 | E8: 0 | F8: 0 | G8: 0 | H8: 0 | I8: 0 | J8: 0 | K8: 0 | L8: 0 | M8: 0 | N8: 0 | O8: 0 | P8: 0 | Q8: 0 | R8: 0 | S8: 0 | T8: 0 | U8: 0 | V8: 0 | W8: 0 | X8: 0 | Y8: 0 | Z8: 0 | AA8: 0 | AB8: =D8+J8+P8+V8 -> 0 | AC8: =G8+M8+S8+Y8 -> 0 | AD8: =IFERROR(AB8/SUM(AB8:AC8),0)*100 -> 0
B9: Year 1 | C9: Q4 | D9: 0 | E9: 0 | F9: 0 | G9: 0 | H9: 0 | I9: 0 | J9: 0 | K9: 0 | L9: 0 | M9: 0 | N9: 0 | O9: 0 | P9: 0 | Q9: 0 | R9: 0 | S9: 0 | T9: 0 | U9: 0 | V9: 0 | W9: 0 | X9: 0 | Y9: 0 | Z9: 0 | AA9: 0 | AB9: =D9+J9+P9+V9 -> 0 | AC9: =G9+M9+S9+Y9 -> 0 | AD9: =IFERROR(AB9/SUM(AB9:AC9),0)*100 -> 0
B10: Year 2 | C10: Q1 | D10: 0 | E10: 0 | F10: 0 | G10: 0 | H10: 0 | I10: 0 | J10: 0 | K10: 0 | L10: 0 | M10: 0 | N10: 0 | O10: 0 | P10: 0 | Q10: 0 | R10: 0 | S10: 0 | T10: 0 | U10: 0 | V10: 0 | W10: 0 | X10: 0 | Y10: 0 | Z10: 0 | AA10: 0 | AB10: =D10+J10+P10+V10 -> 0 | AC10: =G10+M10+S10+Y10 -> 0 | AD10: =IFERROR(AB10/SUM(AB10:AC10),0)*100 -> 0 | AE10: =SUM(D10:D13)+SUM(J10:J13)+SUM(P10:P13) +SUM(V10:V13) -> 0
B11: Year 2 | C11: Q2 | D11: 0 | E11: 0 | F11: 0 | G11: 0 | H11: 0 | I11: 0 | J11: 0 | K11: 0 | L11: 0 | M11: 0 | N11: 0 | O11: 0 | P11: 0 | Q11: 0 | R11: 0 | S11: 0 | T11: 0 | U11: 0 | V11: 0 | W11: 0 | X11: 0 | Y11: 0 | Z11: 0 | AA11: 0 | AB11: =D11+J11+P11+V11 -> 0 | AC11: =G11+M11+S11+Y11 -> 0 | AD11: =IFERROR(AB11/SUM(AB11:AC11),0)*100 -> 0
B12: Year 2 | C12: Q3 | D12: 0 | E12: 0 | F12: 0 | G12: 0 | H12: 0 | I12: 0 | J12: 0 | K12: 0 | L12: 0 | M12: 0 | N12: 0 | O12: 0 | P12: 0 | Q12: 0 | R12: 0 | S12: 0 | T12: 0 | U12: 0 | V12: 0 | W12: 0 | X12: 0 | Y12: 0 | Z12: 0 | AA12: 0 | AB12: =D12+J12+P12+V12 -> 0 | AC12: =G12+M12+S12+Y12 -> 0 | AD12: =IFERROR(AB12/SUM(AB12:AC12),0)*100 -> 0
B13: Year 2 | C13: Q4 | D13: 0 | E13: 0 | F13: 0 | G13: 0 | H13: 0 | I13: 0 | J13: 0 | K13: 0 | L13: 0 | M13: 0 | N13: 0 | O13: 0 | P13: 0 | Q13: 0 | R13: 0 | S13: 0 | T13: 0 | U13: 0 | V13: 0 | W13: 0 | X13: 0 | Y13: 0 | Z13: 0 | AA13: 0 | AB13: =D13+J13+P13+V13 -> 0 | AC13: =G13+M13+S13+Y13 -> 0 | AD13: =IFERROR(AB13/SUM(AB13:AC13),0)*100 -> 0
B14: Year 3 | C14: Q1 | D14: 0 | E14: 0 | F14: 0 | G14: 0 | H14: 0 | I14: 0 | J14: 0 | K14: 0 | L14: 0 | M14: 0 | N14: 0 | O14: 0 | P14: 0 | Q14: 0 | R14: 0 | S14: 0 | T14: 0 | U14: 0 | V14: 0 | W14: 0 | X14: 0 | Y14: 0 | Z14: 0 | AA14: 0 | AB14: =D14+J14+P14+V14 -> 0 | AC14: =G14+M14+S14+Y14 -> 0 | AD14: =IFERROR(AB14/SUM(AB14:AC14),0)*100 -> 0 | AE14: =SUM(D14:D17)+SUM(J14:J17)+SUM(P14:P17) +SUM(V14:V17) -> 0
B15: Year 3 | C15: Q2 | D15: 0 | E15: 0 | F15: 0 | G15: 0 | H15: 0 | I15: 0 | J15: 0 | K15: 0 | L15: 0 | M15: 0 | N15: 0 | O15: 0 | P15: 0 | Q15: 0 | R15: 0 | S15: 0 | T15: 0 | U15: 0 | V15: 0 | W15: 0 | X15: 0 | Y15: 0 | Z15: 0 | AA15: 0 | AB15: =D15+J15+P15+V15 -> 0 | AC15: =G15+M15+S15+Y15 -> 0 | AD15: =IFERROR(AB15/SUM(AB15:AC15),0)*100 -> 0
B16: Year 3 | C16: Q3 | D16: 0 | E16: 0 | F16: 0 | G16: 0 | H16: 0 | I16: 0 | J16: 0 | K16: 0 | L16: 0 | M16: 0 | N16: 0 | O16: 0 | P16: 0 | Q16: 0 | R16: 0 | S16: 0 | T16: 0 | U16: 0 | V16: 0 | W16: 0 | X16: 0 | Y16: 0 | Z16: 0 | AA16: 0 | AB16: =D16+J16+P16+V16 -> 0 | AC16: =G16+M16+S16+Y16 -> 0 | AD16: =IFERROR(AB16/SUM(AB16:AC16),0)*100 -> 0
B17: Year 3 | C17: Q4 | D17: 0 | E17: 0 | F17: 0 | G17: 0 | H17: 0 | I17: 0 | J17: 0 | K17: 0 | L17: 0 | M17: 0 | N17: 0 | O17: 0 | P17: 0 | Q17: 0 | R17: 0 | S17: 0 | T17: 0 | U17: 0 | V17: 0 | W17: 0 | X17: 0 | Y17: 0 | Z17: 0 | AA17: 0 | AB17: =D17+J17+P17+V17 -> 0 | AC17: =G17+M17+S17+Y17 -> 0 | AD17: =IFERROR(AB17/SUM(AB17:AC17),0)*100 -> 0
B18: Year 4 | C18: Q1 | D18: 0 | E18: 0 | F18: 0 | G18: 0 | H18: 0 | I18: 0 | J18: 0 | K18: 0 | L18: 0 | M18: 0 | N18: 0 | O18: 0 | P18: 0 | Q18: 0 | R18: 0 | S18: 0 | T18: 0 | U18: 0 | V18: 0 | W18: 0 | X18: 0 | Y18: 0 | Z18: 0 | AA18: 0 | AB18: =D18+J18+P18+V18 -> 0 | AC18: =G18+M18+S18+Y18 -> 0 | AD18: =IFERROR(AB18/SUM(AB18:AC18),0)*100 -> 0 | AE18: =SUM(D18:D21)+SUM(J18:J21)+SUM(P18:P21) +SUM(V18:V21) -> 0
B19: Year 4 | C19: Q2 | D19: 0 | E19: 0 | F19: 0 | G19: 0 | H19: 0 | I19: 0 | J19: 0 | K19: 0 | L19: 0 | M19: 0 | N19: 0 | O19: 0 | P19: 0 | Q19: 0 | R19: 0 | S19: 0 | T19: 0 | U19: 0 | V19: 0 | W19: 0 | X19: 0 | Y19: 0 | Z19: 0 | AA19: 0 | AB19: =D19+J19+P19+V19 -> 0 | AC19: =G19+M19+S19+Y19 -> 0 | AD19: =IFERROR(AB19/SUM(AB19:AC19),0)*100 -> 0
B20: Year 4 | C20: Q3 | D20: 0 | E20: 0 | F20: 0 | G20: 0 | H20: 0 | I20: 0 | J20: 0 | K20: 0 | L20: 0 | M20: 0 | N20: 0 | O20: 0 | P20: 0 | Q20: 0 | R20: 0 | S20: 0 | T20: 0 | U20: 0 | V20: 0 | W20: 0 | X20: 0 | Y20: 0 | Z20: 0 | AA20: 0 | AB20: =D20+J20+P20+V20 -> 0 | AC20: =G20+M20+S20+Y20 -> 0 | AD20: =IFERROR(AB20/SUM(AB20:AC20),0)*100 -> 0
B21: Year 4 | C21: Q4 | D21: 0 | E21: 0 | F21: 0 | G21: 0 | H21: 0 | I21: 0 | J21: 0 | K21: 0 | L21: 0 | M21: 0 | N21: 0 | O21: 0 | P21: 0 | Q21: 0 | R21: 0 | S21: 0 | T21: 0 | U21: 0 | V21: 0 | W21: 0 | X21: 0 | Y21: 0 | Z21: 0 | AA21: 0 | AB21: =D21+J21+P21+V21 -> 0 | AC21: =G21+M21+S21+Y21 -> 0 | AD21: =IFERROR(AB21/SUM(AB21:AC21),0)*100 -> 0
B22: Year 5 | C22: Q1 | D22: 0 | E22: 0 | F22: 0 | G22: 0 | H22: 0 | I22: 0 | J22: 0 | K22: 0 | L22: 0 | M22: 0 | N22: 0 | O22: 0 | P22: 0 | Q22: 0 | R22: 0 | S22: 0 | T22: 0 | U22: 0 | V22: 0 | W22: 0 | X22: 0 | Y22: 0 | Z22: 0 | AA22: 0 | AB22: =D22+J22+P22+V22 -> 0 | AC22: =G22+M22+S22+Y22 -> 0 | AD22: =IFERROR(AB22/SUM(AB22:AC22),0)*100 -> 0 | AE22: =SUM(D22:D25)+SUM(J22:J25)+SUM(P22:P25) +SUM(V22:V25) -> 0
B23: Year 5 | C23: Q2 | D23: 0 | E23: 0 | F23: 0 | G23: 0 | H23: 0 | I23: 0 | J23: 0 | K23: 0 | L23: 0 | M23: 0 | N23: 0 | O23: 0 | P23: 0 | Q23: 0 | R23: 0 | S23: 0 | T23: 0 | U23: 0 | V23: 0 | W23: 0 | X23: 0 | Y23: 0 | Z23: 0 | AA23: 0 | AB23: =D23+J23+P23+V23 -> 0 | AC23: =G23+M23+S23+Y23 -> 0 | AD23: =IFERROR(AB23/SUM(AB23:AC23),0)*100 -> 0
B24: Year 5 | C24: Q3 | D24: 0 | E24: 0 | F24: 0 | G24: 0 | H24: 0 | I24: 0 | J24: 0 | K24: 0 | L24: 0 | M24: 0 | N24: 0 | O24: 0 | P24: 0 | Q24: 0 | R24: 0 | S24: 0 | T24: 0 | U24: 0 | V24: 0 | W24: 0 | X24: 0 | Y24: 0 | Z24: 0 | AA24: 0 | AB24: =D24+J24+P24+V24 -> 0 | AC24: =G24+M24+S24+Y24 -> 0 | AD24: =IFERROR(AB24/SUM(AB24:AC24),0)*100 -> 0
B25: Year 5 | C25: Q4 | D25: 0 | E25: 0 | F25: 0 | G25: 0 | H25: 0 | I25: 0 | J25: 0 | K25: 0 | L25: 0 | M25: 0 | N25: 0 | O25: 0 | P25: 0 | Q25: 0 | R25: 0 | S25: 0 | T25: 0 | U25: 0 | V25: 0 | W25: 0 | X25: 0 | Y25: 0 | Z25: 0 | AA25: 0 | AB25: =D25+J25+P25+V25 -> 0 | AC25: =G25+M25+S25+Y25 -> 0 | AD25: =IFERROR(AB25/SUM(AB25:AC25),0)*100 -> 0
B26: Year 6 | C26: Q1 | D26: 0 | E26: 0 | F26: 0 | G26: 0 | H26: 0 | I26: 0 | J26: 0 | K26: 0 | L26: 0 | M26: 0 | N26: 0 | O26: 0 | P26: 0 | Q26: 0 | R26: 0 | S26: 0 | T26: 0 | U26: 0 | V26: 0 | W26: 0 | X26: 0 | Y26: 0 | Z26: 0 | AA26: 0 | AB26: =D26+J26+P26+V26 -> 0 | AC26: =G26+M26+S26+Y26 -> 0 | AD26: =IFERROR(AB26/SUM(AB26:AC26),0)*100 -> 0 | AE26: =SUM(D26:D29)+SUM(J26:J29)+SUM(P26:P29) +SUM(V26:V29) -> 0
B27: Year 6 | C27: Q2 | D27: 0 | E27: 0 | F27: 0 | G27: 0 | H27: 0 | I27: 0 | J27: 0 | K27: 0 | L27: 0 | M27: 0 | N27: 0 | O27: 0 | P27: 0 | Q27: 0 | R27: 0 | S27: 0 | T27: 0 | U27: 0 | V27: 0 | W27: 0 | X27: 0 | Y27: 0 | Z27: 0 | AA27: 0 | AB27: =D27+J27+P27+V27 -> 0 | AC27: =G27+M27+S27+Y27 -> 0 | AD27: =IFERROR(AB27/SUM(AB27:AC27),0)*100 -> 0
B28: Year 6 | C28: Q3 | D28: 0 | E28: 0 | F28: 0 | G28: 0 | H28: 0 | I28: 0 | J28: 0 | K28: 0 | L28: 0 | M28: 0 | N28: 0 | O28: 0 | P28: 0 | Q28: 0 | R28: 0 | S28: 0 | T28: 0 | U28: 0 | V28: 0 | W28: 0 | X28: 0 | Y28: 0 | Z28: 0 | AA28: 0 | AB28: =D28+J28+P28+V28 -> 0 | AC28: =G28+M28+S28+Y28 -> 0 | AD28: =IFERROR(AB28/SUM(AB28:AC28),0)*100 -> 0
B29: Year 6 | C29: Q4 | D29: 0 | E29: 0 | F29: 0 | G29: 0 | H29: 0 | I29: 0 | J29: 0 | K29: 0 | L29: 0 | M29: 0 | N29: 0 | O29: 0 | P29: 0 | Q29: 0 | R29: 0 | S29: 0 | T29: 0 | U29: 0 | V29: 0 | W29: 0 | X29: 0 | Y29: 0 | Z29: 0 | AA29: 0 | AB29: =D29+J29+P29+V29 -> 0 | AC29: =G29+M29+S29+Y29 -> 0 | AD29: =IFERROR(AB29/SUM(AB29:AC29),0)*100 -> 0

Sheet Table C Goods 
B1: TM-24-1339 -: GOODS : Material/Products to be utilized in the execution of the contract scope
B2: Key :
B3: To be completed by Contractor - Updates shall be based on contract duration period. For example the contract duartion for 2 years then bidders to update the table below for 2 years only.
B4: NOT to be completed by Contractor - auto/formula completion
B5: To Add new rows to the table, Select the entire last row of the table and drag it to create the number of new rows required.please DON'T insert a new row in the middle of the table.
B6: Made-in-Oman Goods Utilised in Contract Execution from Nationally Registered Suppliers | M6: =SUMIFS(M14:M1014,B14:B1014,"Made_In_Oman",I14:I1014,"NRS") -> 0
B7: Made-in-Oman Goods Utilised in Contract Execution from SMEs | M7: =SUMIFS(M14:M1014,B14:B1014,"Made_In_Oman",I14:I1014,"SME") -> 0
B8: Made-in-Oman Goods Utilised in Contract Execution procured from LCCs | M8: =SUMIFS(M14:M1014,B14:B1014,"Made_In_Oman",J14:J1014,"YES") -> 0
B9: NOT Made-in-Oman Goods Utilised in Contract Execution procured from National Registered Companies | M9: =SUMIFS(M14:M1014,B14:B1014,"NonMade_In_Oman",I14:I1014,"NRS") -> 0
B10: NOT Made-in-Oman Goods Utilised in Contract Execution procured from Foreign Companies | M10: =SUMIFS(M14:M1014,B14:B1014,"NonMade_In_Oman",I14:I1014,"FRS") -> 0
B11: NOT Made-in-Oman Goods Utilised in Contract Execution procured from SMEs | M11: =SUMIFS(M14:M1014,B14:B1014,"NonMade_In_Oman",I14:I1014,"SME") -> 0
B12: NOT Made-in-Oman Goods Utilised in Contract Execution procured from LCCs | M12: =SUMIFS(M14:M1014,B14:B1014,"NonMade_In_Oman",J14:J1014,"YES") -> 0
B13: Procurement Type | C13: Year | D13: Period | E13: Goods Category | F13: Goods Sub Category | G13: Company Name/JSRS/CR | H13: JSRS Category | I13: Vendory Category (Read Only) | J13: LCC | K13: SME/LCC Obligation Type | L13: Summary Description | M13: Value (USD)
I14: =IF(H14="Large","NRS",IF(H14="International","FRS",IF(H14="SME - Medium","SME",IF(H14="SME - Micro","SME",IF(H14="SME - Small","SME",""))))) | J14: =IF(B14="","","No")
I15: =IF(H15="Large","NRS",IF(H15="International","FRS",IF(H15="SME - Medium","SME",IF(H15="SME - Micro","SME",IF(H15="SME - Small","SME",""))))) | J15: =IF(B15="","","No")
I16: =IF(H16="Large","NRS",IF(H16="International","FRS",IF(H16="SME - Medium","SME",IF(H16="SME - Micro","SME",IF(H16="SME - Small","SME",""))))) | J16: =IF(B16="","","No")
I17: =IF(H17="Large","NRS",IF(H17="International","FRS",IF(H17="SME - Medium","SME",IF(H17="SME - Micro","SME",IF(H17="SME - Small","SME",""))))) | J17: =IF(B17="","","No")
I18: =IF(H18="Large","NRS",IF(H18="International","FRS",IF(H18="SME - Medium","SME",IF(H18="SME - Micro","SME",IF(H18="SME - Small","SME",""))))) | J18: =IF(B18="","","No")
I19: =IF(H19="Large","NRS",IF(H19="International","FRS",IF(H19="SME - Medium","SME",IF(H19="SME - Micro","SME",IF(H19="SME - Small","SME",""))))) | J19: =IF(B19="","","No")
I20: =IF(H20="Large","NRS",IF(H20="International","FRS",IF(H20="SME - Medium","SME",IF(H20="SME - Micro","SME",IF(H20="SME - Small","SME",""))))) | J20: =IF(B20="","","No")
I21: =IF(H21="Large","NRS",IF(H21="International","FRS",IF(H21="SME - Medium","SME",IF(H21="SME - Micro","SME",IF(H21="SME - Small","SME",""))))) | J21: =IF(B21="","","No")
I22: =IF(H22="Large","NRS",IF(H22="International","FRS",IF(H22="SME - Medium","SME",IF(H22="SME - Micro","SME",IF(H22="SME - Small","SME",""))))) | J22: =IF(B22="","","No")
I23: =IF(H23="Large","NRS",IF(H23="International","FRS",IF(H23="SME - Medium","SME",IF(H23="SME - Micro","SME",IF(H23="SME - Small","SME",""))))) | J23: =IF(B23="","","No")
I24: =IF(H24="Large","NRS",IF(H24="International","FRS",IF(H24="SME - Medium","SME",IF(H24="SME - Micro","SME",IF(H24="SME - Small","SME",""))))) | J24: =IF(B24="","","No")
I25: =IF(H25="Large","NRS",IF(H25="International","FRS",IF(H25="SME - Medium","SME",IF(H25="SME - Micro","SME",IF(H25="SME - Small","SME",""))))) | J25: =IF(B25="","","No")
... I1014: =IF(H1014="Large","NRS",IF(H1014="International","FRS",IF(H1014="SME - Medium","SME",IF(H1014="SME - Micro","SME",IF(H1014="SME - Small","SME",""))))) | J1014: =IF(B1014="","","No")

Sheet Table D Services
B1: TM-24-1339 -: Services
B2: Key :
B3: To be completed by Contractor - Updates shall be based on contract duration period. For example the contract duartion for 2 years then bidders to update the table below for 2 years only.
B4: NOT to be completed by Contractor - auto/formula completion
B5: To Add new rows to the table, Select the entire last row of the table and drag it to create the number of new rows required.please DON'T insert a new row in the middle of the table.
B6: Local Sourcing of Services from Nationally-Registered Supplier Utilised in Contract Execution | L6: =SUMIF(H11:H1444, "NRS", L11:L1444) -> 0
B7: Sourcing of Services from Foreign Companies Utilised in Contract Execution by Foreign Companies | L7: =SUMIF(H11:H1444, "FRS", L11:L1444) -> 0
B8: Sourcing of Services from SMEs | L8: =SUMIF(H11:H1444, "SME", L11:L1444) -> 0
B9: Sourcing of Services from LCC | L9: =SUMIF(I11:I1444, "Yes", L11:L1444) -> 0
B10: Year | C10: Period | D10: Service Category | E10: Service Sub Category | F10: Service Provider | G10: JSRS Category | H10: Vendory Category (Read Only) | I10: LCC | J10: SME/LCC Obligation Type | K10: Summary Description | L10: Value (USD)
H11: =IF(G11="Large","NRS",IF(G11="International","FRS",IF(G11="SME - Medium","SME",IF(G11="SME - Micro","SME",IF(G11="SME - Small","SME",""))))) | I11: =IF(H11="FRS","No","")
H12: =IF(G12="Large","NRS",IF(G12="International","FRS",IF(G12="SME - Medium","SME",IF(G12="SME - Micro","SME",IF(G12="SME - Small","SME",""))))) | I12: =IF(H12="FRS","No","")
H13: =IF(G13="Large","NRS",IF(G13="International","FRS",IF(G13="SME - Medium","SME",IF(G13="SME - Micro","SME",IF(G13="SME - Small","SME",""))))) | I13: =IF(H13="FRS","No","")
H14: =IF(G14="Large","NRS",IF(G14="International","FRS",IF(G14="SME - Medium","SME",IF(G14="SME - Micro","SME",IF(G14="SME - Small","SME",""))))) | I14: =IF(H14="FRS","No","")
H15: =IF(G15="Large","NRS",IF(G15="International","FRS",IF(G15="SME - Medium","SME",IF(G15="SME - Micro","SME",IF(G15="SME - Small","SME",""))))) | I15: =IF(H15="FRS","No","")
H16: =IF(G16="Large","NRS",IF(G16="International","FRS",IF(G16="SME - Medium","SME",IF(G16="SME - Micro","SME",IF(G16="SME - Small","SME",""))))) | I16: =IF(H16="FRS","No","")
H17: =IF(G17="Large","NRS",IF(G17="International","FRS",IF(G17="SME - Medium","SME",IF(G17="SME - Micro","SME",IF(G17="SME - Small","SME",""))))) | I17: =IF(H17="FRS","No","")
H18: =IF(G18="Large","NRS",IF(G18="International","FRS",IF(G18="SME - Medium","SME",IF(G18="SME - Micro","SME",IF(G18="SME - Small","SME",""))))) | I18: =IF(H18="FRS","No","")
H19: =IF(G19="Large","NRS",IF(G19="International","FRS",IF(G19="SME - Medium","SME",IF(G19="SME - Micro","SME",IF(G19="SME - Small","SME",""))))) | I19: =IF(H19="FRS","No","")
H20: =IF(G20="Large","NRS",IF(G20="International","FRS",IF(G20="SME - Medium","SME",IF(G20="SME - Micro","SME",IF(G20="SME - Small","SME",""))))) | I20: =IF(H20="FRS","No","")
H21: =IF(G21="Large","NRS",IF(G21="International","FRS",IF(G21="SME - Medium","SME",IF(G21="SME - Micro","SME",IF(G21="SME - Small","SME",""))))) | I21: =IF(H21="FRS","No","")
H22: =IF(G22="Large","NRS",IF(G22="International","FRS",IF(G22="SME - Medium","SME",IF(G22="SME - Micro","SME",IF(G22="SME - Small","SME",""))))) | I22: =IF(H22="FRS","No","")
... H1011: =IF(G1011="Large","NRS",IF(G1011="International","FRS",IF(G1011="SME - Medium","SME",IF(G1011="SME - Micro","SME",IF(G1011="SME - Small","SME",""))))) | I1011: =IF(H1011="FRS","No","")

Sheet Table E IndirectICV
B1: Table E - IndirectICV Element
B2: Key :
B3: To be completed by Contractor - Updates shall be based on contract duration period. For example the contract duartion for 2 years then bidders to update the table below for 2 years only.
B4: NOT to be completed by Contractor - auto/formula completion
B5: To Add new rows to the table, Select the entire last row of the table and drag it to create the number of new rows required.please DON'T insert a new row in the middle of the table.
B6: E - IndirectICV Value | G6: =SUM(G8:G993) -> 0
B7: Category | C7: Sub Category | D7: Year | E7: Period | F7: Summary Description | G7: Value(USD)

Sheet Summary
A1: TABLE E - Tender Plan Summary
A2: Tender Plan summary Table for the duration of the Contract
B4: Total Tender Summary
B6: Investments in Fixed Assets | F6: Existing Inv | G6: ='Table A Investment'!F7 -> 0
F7: Future Inv | G7: ='Table A Investment'!F6 -> 0
B8: Workforce Utilized to Execute Contract | D8: overall | E8: Omanis | F8: Headcount | G8: ='Table B Workforce - Contractor'!H18 -> 0
F9: Man-hours | G9: ='Table B Workforce - Contractor'!I18 -> 0
F10: Payroll | G10: ='Table B Workforce - Contractor'!J18 -> 0
F11: % Omanis Workforce | G11: ='Table B Workforce - Contractor'!H20 -> 0
E12: Expatriate | F12: Headcount | G12: ='Table B Workforce - Contractor'!H19 -> 0
F13: Man-hours | G13: ='Table B Workforce - Contractor'!I19 -> 0
F14: Payroll | G14: ='Table B Workforce - Contractor'!J19 -> 0
B15: Goods | D15: Made in Oman | F15: NRS | G15: ='Table C Goods '!M6 -> 0
F16: SME | G16: ='Table C Goods '!M7 -> 0
F17: LCC | G17: ='Table C Goods '!M8 -> 0
D18: Non-Made-in-Oman Goods Utilised in Contract Execution | F18: NRS | G18: ='Table C Goods '!M9 -> 0
F19: FRS | G19: ='Table C Goods '!M10 -> 0
F20: SME | G20: ='Table C Goods '!M11 -> 0
F21: LCC | G21: ='Table C Goods '!M12 -> 0
B22: Services | F22: NRS | G22: ='Table D Services'!L6 -> 0
F23: FRS | G23: ='Table D Services'!L7 -> 0
F24: SME | G24: ='Table D Services'!L8 -> 0
F25: LCC | G25: ='Table D Services'!L9 -> 0

Sheet Lookup
A1: Investment Category | C1: Goods Category Name | E1: Category of Vendor | G1: Goods Procurement Category | I1: Services Procurement Category | J1: LocalSourcingofServices_D1 | K1: ForeignSourcingofServices_D2 | M1: Services Category Name | O1: Goods | V1: Services
A2: Repairing Facility | C2: Accessories | E2: Large | G2: MadeinOman | I2: ServicesSourced_NationalRegisteredCompany | J2: SME | K2: N/A | M2: Basis for Design / Concept | O2: Chemical_Energy | P2: Misc_Goods | Q2: EngineeringProjectConstruction | R2: Equipment | S2: Wells | V2: Chemical_Energy_Services | W2: Corporate_Services | X2: EPC_Services | Y2: EquipmentServices | Z2: Geoscience_Services | AA2: Misc_Services | AB2: Wells_Services
A3: Service & Maintenance Facility | C3: Actuators & Relays | E3: SME | G3: NotMadeinOman_ProcuredfromNationallyRegisteredCompany | I3: ServicesSourced_ForeignRegisteredCompany | J3: LCC | M3: Building Construction | O3: Diesel | P3: Facility Maintenance Materials & Equipment | Q3: Architectural & Building Materials | R3: Electric Cables & Accessories | S3: Artificial Lift Systems | V3: Chemical QA & Performance | W3: Access Control | X3: Basis for Design / Concept | Y3: Calibration | Z3: Exploration Laboratory and Coreshed | AA3: Cargo Management | AB3: Artificial Lift Systems
A4: Heavy Equipment | C4: Actuators Valve | E4: LCC | G4: NotMadeinOman_ProcuredfromForeignRegisteredCompany | J4: National Registered Supplier | M4: Bulk Hazardous Liquid | O4: Fuel Oils | P4: CCTV | Q4: Building Structures | R4: Electrical Motors | S4: Cementing Accessories | V4: Lab Testing | W4: Air, Land & Fleet/Lease | X4: Civils Construction Services | Y4: Control & Automation Systems Services | Z4: Field / Surface Geology | AA4: Completions & Commisioning Services | AB4: Casing & Tubing Running Services
A5: Rigs & Hoists | C5: After Market | E5: SLCC | M5: Calibration | O5: Natural Gas | P5: End User Computing (EUC) | Q5: Civil Bulk Materials | R5: Generators | S5: Completions and Liner Hanger Systems | V5: Surface Services | W5: Catering | X5: Decommissioning Services | Y5: Field Control and Maintenance Services | Z5: Geoinformation Management | AA5: Environmental Services | AB5: Cementing & Stimulation Services
A6: Manufacturing Facility | C6: Air Coolers | E6: N/A | M6: Cargo Clearance | O6: Utilities | P6: Hosting & Storage (H&S) | Q6: Insulation & Refractory Materials | R6: Line, Overhead Line and Accessories | S6: Down Hole Pressure Control Equipment | V6: Sub Surface Services | W6: Contract Labor | X6: Demolition & Cleanup Services | Y6: Rotating Equipment After Market Service | Z6: Geological Services | AA6: Fire & Safety Equipment | AB6: Cementing Accessories
A7: Warehouse | C7: Antifoam | M7: Cargo Clearance Services | O7: Water | P7: Catering | Q7: Civils Construction Services | R7: Switchgears | S7: Drilling & Fishing Equipment & Tools | V7: Chemical Analysis | W7: Education Providers | X7: Detail Design & As Built | Z7: Geophysical Services | AA7: Freight Forwarding | AB7: Coiled Tubing Services
A8: New Production Line | C8: Automobiles | M8: Cargo Management | O8: Bulk Chemicals | P8: Office Equipment & Services | Q8: Electrical & Instrumentation Construction Services | R8: Transformers | S8: Drilling Bits | W8: Emergency Response | X8: Earthmoving Work | Z8: Integrated Specialist Geological Services | AA8: General Maintenance | AB8: Completions and Liner Hanger Systems
C9: Ball Valve | M9: Casing & Tubing Running Services / Casing While Drilling | O9: Commercial Chemicals | P9: Access Control | Q9: Mechanical Construction Services | R9: Uninterrupted Power Systems | S9: Drilling Machinery Sand Mud Control Instruments | W9: Events, Hotels & Agencies | X9: Electrical Construction Services | Z9: Quantitative Interpretation | AA9: Health Services | AB9: Coring Services
C10: Batteries/Accessories | M10: Catering | O10: Miscellaneous Chemicals | P10: Emergency Response | Q10: Mechanical/Electrical & Instrumentation | R10: Fasteners | S10: Inflatables / Expandables | W10: Facility Management & Maintenance Services | X10: FEED | Z10: Remote Sensing | AA10: HSE Advisory Services | AB10: Directional Drilling Services
C11: Beam Pumps | M11: Catering Services | O11: Oil Based Mud Chemicals | P11: Fencing | Q11: General Packages | R11: Fittings | S11: OCTG Accessories & Inspection Services | W11: Fencing | X11: Flowline Construction | Z11: Research Deployment | AA11: Lab Testing | AB11: Down Hole Pressure Control Equipment
C12: BOP and Accessories | M12: Cathodic Proctection | O12: Salts | P12: Telecommunications | Q12: Process Packages | R12: Flanges | S12: OCTG Coiled Tubing Tools and Accessories | W12: Finance/Legal/Insurance/Marketing | X12: General Civil Work | Z12: Reservior Services | AA12: Landscapping | AB12: Drilling & Fishing Equipment & Tools
C13: Bulk | M13: Cementing & Stimulation | O13: Specialty Chemicals | P13: Software & Licenses | R13: Gaskets & O-rings | S13: Production Surface Equipment and Accessories | W13: HR, Consulting & Services | X13: General Packages | Z13: Seismic Acquisition | AA13: Lifting Services | AB13: Drilling Bits
C14: Burners, Flare Systems & Flame arrestors | M14: Chemicals Transportation | O14: Sub-Surface Polymers | P14: Fire & Safety Equipment | R14: Hardware Tools & Consumables | S14: Production Well Test and Monitoring Instruments | W14: HSE & Government Relations | X14: Installation Services | Z14: Seismic Processing | AA14: Logistic & Transportation | AB14: Drilling Equipment Services
C15: Butterfly Valve | M15: Civil Services | O15: Antifoam | P15: Health Services | R15: Hoses | S15: Wellhead Eqmt X-mas Trees BOP & Accessories | W15: IT Consulting | X15: Instrumentation Construction Services | Z15: Surveying & Mapping | AA15: Maintenance & Services | AB15: Drilling Machinery Sand Mud Control Instruments
C16: Cables & Accessories | M16: Coiled Tubing Services | O16: Corrosion Chemicals | P16: Safety Services | R16: Process Pipe | S16: Wireline Equipment and Accessories | W16: IT Services & Maintenance | X16: Lining/Coating/Paimtimg | AA16: Materials Management Services | AB16: Fishing Milling & Cutting Services
C17: Cables & Accessories | M17: Completions Services | O17: Dehydration Chemicals | R17: Spades/Spectacle Blinds | S17: Fishing Milling & Cutting Services | W17: IT Systems Development & Management | X17: Mechanical Construction Services | AA17: Passenger Management Services - Aviation | AB17: Fluid Filteration
C18: Casing and Tubing | M18: Compressor Services | O18: Deoiler / F46 | R18: Steam Traps | S18: Wellheads / Xtrees | W18: Managed Network Services (MNS) | X18: NDT Work | AA18: Passenger Management Services - Land | AB18: H2S Services
C19: Catering | M19: Compressors Services | O19: Drag Reducer | R19: Control Valves | W19: Media Services | X19: OHL Construction & Services | AA19: Passenger Management Services - Light Fleet | AB19: Heavy Rigs
C20: Ceiling Panels & Roof Decking | M20: Concrete Services | O20: H2S Scavenger | R20: Field Sensors | W20: Office Equipment & Services | X20: Pigging & Testing | AA20: Production Testing & Monitoring | AB20: High Pressure Fracturing
C21: Cellarless Wellhead | M21: Consultancy Services | O21: Industrial Gases | R21: Fire & Gas Detectors | W21: Office Management Services | X21: Pipeline Maintenance & Construction | AA21: Repair of Hazardous Area | AB21: Inflatables / Expandables
C22: Centrifugal | M22: Control & Automation Systems | O22: Laboratory chemicals | R22: IAE QA Services | W22: Property & Land Services | X22: Plant Construction | AA22: Rock Blasting & Cutting | AB22: Light / Medium Rigs
C23: Check Valve | M23: Control & Automation Systems Services | O23: Scale Inhibitor | R23: Instrument Cables | W23: Research and Consulting | X23: Plugging Services | AA23: Safety Services | AB23: Logging & Perforation
C24: Chemicals | M24: Control Room System | O24: Surface Polymers | R24: Instrument Hook Ups | W24: Software & Licenses | X24: Process Packages | AA24: Secondary Logistics | AB24: Mud & Drilling Chemical Services
C25: Chemicals & Energy | M25: Control Valve Maintenance | O25: Water Treatment | R25: IPF Valves | W25: Telecommunications | X25: Project Inspection, QA & QC | AA25: Special Services | AB25: Mud Logging Services
C26: Christmas Tree | M26: Coring Services | O26: Wax Inhibitor | R26: Local Field Instruments | W26: Telecommunications Services & Maintenance | X26: Project Management | AA26: Specialty Maintenance | AB26: Nitrogen Services
C27: Civil Equipment | M27: Corrosion Inspection | O27: Chemical QA & Performance | R27: Process Automation Systems | W27: Training Providers | X27: Project Services, Contract Services, Handover & IM Delivery | AA27: Topography | AB27: OCTG Accessories & Inspection Services
C28: Cleaning Detergent | M28: Data Communication services | R28: Wellhead Control Panels | X28: Snubbing Services | AA28: Valve Maintenance | AB28: OCTG Coiled Tubing Tools and Accessories
C29: Cleaning Equipment | M29: Detail Design & As Built | R29: Pipe Handling & Lifting Equipment | X29: Tank Construction | AA29: Waste and Air Management | AB29: Production Surface Equipment and Accessories
C30: CO2 Extinguisher | M30: Digital Mapping | R30: Carbon Steel Linepipe / Piping | X30: Technical Manpower | AB30: Production Well Test and Monitoring Instruments
C31: Commercial | M31: Directional Drilling | R31: Corrosion Resistent Alloy (CRA) Materials | X31: Troubleshooting / Engineering Support | AB31: Rig Derricks and Accessories
C32: Communication Equipments | M32: Distribution System | R32: Duplex Stainless Steel Linepipe / Piping | AB32: Rigless Intervention
C33: Completions Equipment | M33: Earthmoving Work | R33: Flexible Pipes | AB33: Road Services
C34: Compressors | M34: Education/Training Services | R34: Linepipe - Non-Metallic | AB34: Site Survey
C35: Computer Hardware | M35: Electrical Engineering Services | R35: Piping Accessories | AB35: Well Abandonment
C36: Computer Peripherals | M36: Electrical Installation & Testing | R36: Air Compressors | AB36: Well Analysis
C37: Concrete Products | M37: Electrical Maintenance | R37: Compressors | AB37: Well Control (Emerg.)
C38: Control Equipment | M38: Electrical Services | R38: Engines | AB38: Well Hoist Services
C39: Control Panels | M39: Engine Services | R39: Pumps | AB39: Well Site Construction
C40: Control Valves | M40: Environmental Services | R40: Turbines | AB40: Well Test
...

Sheet System Values
O1: Period | U1: LCC YN | AC1: JSRS Category | AE1: LCC YN | AQ1: Large | AR1: International
M2: Made_In_Oman | N2: Year 1 | O2: Q1 | P2: Chemicals and Energy | Q2: Antifoam | U2: Yes | X2: Q1 | Y2: Year 1 | AC2: International | AD2: FRS | AE2: Yes | AQ2: SME - Medium | AR2: Large
M3: NonMade_In_Oman | N3: Year 2 | O3: Q2 | P3: Civil and Equipment | Q3: Bulk | U3: No | X3: Q2 | Y3: Year 2 | AC3: Large | AD3: NRS | AE3: No | AQ3: SME - Micro | AR3: SME - Medium
N4: Year 3 | O4: Q3 | P4: Electrical and Equipment | Q4: Chemicals | X4: Q3 | Y4: Year 3 | AC4: SME - Medium | AD4: SME | AQ4: SME - Small | AR4: SME - Micro
N5: Year 4 | O5: Q4 | P5: Health and Safety and Equipment | Q5: Commercial | X5: Q4 | Y5: Year 4 | AC5: SME - Micro | AR5: SME - Small
N6: Year 5 | P6: Instrumentation and Automation and Equipment | Q6: Corrosion and Chemicals | Y6: Year 5 | AC6: SME - Small
N7: Year 6 | P7: IT and Telecom | Q7: Dehydration and Chemicals | Y7: Year 6
P8: Linepipe | Q8: Deoiler and F46
P9: Other and Equipments | Q9: Drag and Reducer
P10: Others | Q10: Electricity
P11: Rotating and Equipment | Q11: Fuel and Oils
P12: Static and MRO and Equipment | Q12: H2S and Scavenger
P13: Wells and Equipment | Q13: Industrial and Gases
Q14: Inhibitor
Q15: Laboratory and chemicals
Q16: Miscellaneous
Q17: Natural and Gas
Q18: Oil and Based and Mud and Chemicals
Q19: Others
Q20: Polymers
Q21: Salts
Q22: Scale and Inhibitor
Q23: Specialty
Q24: Water
Q25: Water and Treatment
... Q154: Automobiles and
Q155: Food and Products | EY155: 6
Q156: Heaters and Boilers and Furnaces
Q157: Kitchen and Catering and
Q158: Miscelleneous
Q159: Office and Furniture and
Q160: Others
Q161: Residential and Furniture
Q162: Stationery and Items
Q163: Warehouse and Equipment
Q164: Workshop and Equipment
Q165: Others
Q166: After and Market
Q167: Beam and Pumps and
... Q240: Xmas and Tree and

Sheet Goods Data
B1: Made-InOman | C1: Non-MadeInOman | D1: Categories
B2: Large | C2: International | D2: Chemicals and Energy | E2: Antifoam | F2: Ceiling and Panels and Roof and Decking | G2: Actuators and Relays | H2: Cleaning and Detergent | I2: Control and Equipment | J2: Batteries and Accessories | K2: Accessories | L2: Automobiles and | M2: Others | N2: After and Market | O2: Actuators and Valve | P2: BOP and and and Accessories
B3: SME - Medium | C3: Large | D3: Civil and Equipment | E3: Bulk | F3: Concrete and Products | G3: Cables and Accessories | H3: Cleaning and Equipment | I3: Control and Valves | J3: Cables and Accessories | K3: CRA and Materials | L3: Food and Products | N3: Beam and Pumps and | O3: Air and Coolers | P3: Casing and and and Tubing and
B4: SME - Micro | C4: SME - Medium | D4: Electrical and Equipment | E4: Chemicals | F4: Doors and Windows | G4: Control and Panels and | H4: CO2 and Extinguisher | I4: Control and IPF and Valves | J4: Communication and Equipments | K4: Flexible and Pipes | L4: Heaters and Boilers and Furnaces | N4: Centrifugal and | O4: Ball and Valve | P4: Cellarless and Wellhead
B5: SME - Small | C5: SME - Micro | D5: Health and Safety and Equipment | E5: Commercial | F5: Fencing and Barriers | G5: Distribution and Board | H5: Detectors | I5: Detection and Instruments | J5: Computer and Hardware | K5: HFW and Carbon and Steel and | L5: Kitchen and Catering and | N5: Compressors | O5: Burners and Flare and Systems and Flame and arrestors | P5: Christmas and Tree and
C6: SME - Small | D6: Instrumentation and Automation and Equipment | E6: Corrosion and Chemicals | F6: Fencing and Barriers and Materials | G6: Earthing and Fittings | H6: Dry and Powder and Extinguisher | I6: Field and Sensors | J6: Computer and Peripherals | K6: HSAW and Carbon and Steel | L6: Miscelleneous | N6: Engines | O6: Butterfly and Valve | P6: Completions and Equipment
D7: IT and Telecom | E7: Dehydration and Chemicals | F7: Hardware and Building and Materials | G7: Electric and Cables and Accessories | H7: Extinguishers | I7: Fire and Gas and Detectors | J7: Database and Equipment | K7: Linepipe and Non and Metallic | L7: Office and Furniture and | N7: Gas and Turbines | O7: Check and Valve | P7: Downhole and Gauges
D8: Linepipe | E8: Deoiler and F46 | F8: Hardware and Materials | G8: Electrical and Motors | H8: Fire and Safety and Equipment | I8: Flow and Instruments | J8: Global and Positioning and System and GPS and Accessories | K8: LSAW and Carbon and Steel | L8: Others | N8: Instrument and Air and Compressor and | O8: Fasteners | P8: Drilling and Bits
D9: Other and Equipments | E9: Drag and Reducer | F9: Heating and Air and Condition and Units | G9: Feeder and Pillars | H9: Fire and Hose and Reels | I9: Hook and Ups | J9: GPS and Accessories | K9: Others | L9: Residential and Furniture | N9: Other and Turbines | O9: Filter and Separators and Filter and s and Element | P9: ESP and PCP and Pump
D10: Others | E10: Electricity | F10: Irrigation and Equipment | G10: Generators | H10: H2S and Gas and Monitor | I10: Instrument and Cables | J10: Media and Converter | K10: Seamless and Carbon and Steel | L10: Stationery and Items | N10: Others | O10: Fired and Equipment | P10: ESP and Pump
D11: Rotating and Equipment | E11: Fuel and Oils | F11: Light and Fittings | G11: HVAC | H11: Heat and Detectors | I11: Instrument and Hook and Ups | J11: Modems | K11: Welded and Pipes | L11: Warehouse and Equipment | N11: Pumps | O11: Fittings | P11: Fishing and Repairing and Tool
D12: Static and MRO and Equipment | E12: H2S and Scavenger | F12: Others | G12: Isolators and Disconnectors | H12: Hydro and Carbon and Personnel and Monitors | I12: IPF and Valves | J12: Others | L12: Workshop and Equipment | N12: Steam and Turbines | O12: Flanges | P12: Gaslift and Valves
D13: Wells and Equipment | E13: Industrial and Gases | F13: Painting and Decorating | G13: Lighting and Columns and Fittings | H13: Laboratory and Equipment | I13: Level and Instruments | J13: Personal and Communication and Equipment | N13: Turbines | O13: Gaskets and O and rings | P13: Inflatables and Expandables
E14: Inhibitor | F14: Painting and Decorating and Materials | G14: Motors | H14: Lifting and Equipment | I14: Local and Field and Instruments | J14: Phones and Fax and and and Accessories | N14: Turbo and Expanders | O14: Gate and Valve | P14: Liner and Hangers and Assemblies
E15: Laboratory and chemicals | F15: Pipes and Fittings | G15: Others | H15: Medical and Equipment | I15: Metering and Equipment | J15: Power and Supply and Rectifiers and Covertors and Voltage | O15: Globe and Valve | P15: Mandrels
E16: Miscellaneous | F16: Reinforcement and Steel | G16: Plugs and Connectors | H16: Medical and Equpment | I16: Others | J16: Printers and Accessories | O16: Hoses | P16: OCTG and Accessories and Inspection and Services
E17: Natural and Gas | F17: Roof and Sheeting and Insulations | G17: Rectifiers and Inverters and Converters | H17: Monitors | I17: Pressure and Instruments | J17: Printers and Toners and amd and Catridges | O17: Hoses and Tubes and Pipes | P17: Oil and Country and Tubular and Goods
E18: Oil and Based and Mud and Chemicals | F18: Sanitaryware | G18: Solar and Power and | H18: Multi and Detectors and Type and Personal and Detector | I18: Process and Automation and Systems | J18: Projectors and Audio and Video and Equipment | O18: Hydraulic and Units | P18: Others
E19: Others | F19: Sanitaryware and Items | G19: Switches and Fuses and Conduit | H19: Others | I19: Quality | J19: Radio and Antennas and Towers | O19: Mixers and Crushers and Accumulators | P19: Packer and Accessories and
E20: Polymers | F20: Sign and Board | G20: Switchgears | H20: Portable and Multi and Gas and Monitor | I20: Regulators | J20: Radios and Antennas | O20: Other and Valves | P20: Progressive and Cavity and Pumps
E21: Salts | F21: Signs and Board and Street and Furniture | G21: Terminal and Junction and Boxes | H21: Self and Contained and Breathing and Apparatus and SCBA | I21: Remote and Fieldbus | J21: Rcording and and and Messaging and Equipment | O21: Others | P21: Rods and Suckers
E22: Scale and Inhibitor | F22: Tiles | G22: Transformers | H22: Smoke and Detectors | I22: Temperature and Instruments | J22: Security and System | O22: Pressure and Vessels and Columns and Reactors and | P22: Sand and Control
E23: Specialty | F23: Wall and Flooring and Tiles | G23: Uninterrupted and Power and Systems | H23: Thermal and Detectors | I23: Wellhead and Control and Panel | J23: Systems and Equipment | O23: Process and Pipe | P23: Slickline and Set
E24: Water | F24: Water and Sewage and Pumps | G24: UPS | H24: Water and Extinguisher and | J24: Towers and Mast and Poles | O24: Relief and Valve | P24: Slim and Hole and Wellhead and Equipment
E25: Water and Treatment | F25: Wood and Materials | J25: UPS and System | O25: Safety and Valve | P25: Wellhead and Valves
E26: Wax and Inhibitor | F26: Woods and Materials | O26: Solenoid and Valve | P26: Wellheads and
O27: Spades and Spectacle and Blinds | P27: Wellheads and Accessories
O28: Steam and Traps | P28: Wire and Wrap and and and Pre and Packed and Screens
O29: Tanks and Spheres and Accessories | P29: Wireline and Equipment
O30: Tools and Consumables | P30: Xmas and Tree and
O31: Tubes
O32: Unfired and Heat and Exchangers
O33: Valves
O34: Vessel and Column and Internals

Sheet Service Data
D1: Categories
D2: Civil and Services | E2: Building and Construction | F2: Cathodic and Proctection | G2: Digital and Mapping | H2: Environmental and Services | I2: Control and Automation and Systems and | J2: Data and Communication and services | K2: Bulk and Hazardous and Liquid | L2: Compressor and Services | M2: Catering and Services | N2: Others | O2: and Maintenance and Services | P2: Basis and for and Design and Concept | Q2: Casing and Tubing and Running and Services and Casing and While and Drilling
D3: Electrical and Services | E3: Concrete and Services | F3: Distribution and System and | G3: Exploration and Laboratory and and and Coreshed | H3: Fire and Safety and Services | I3: Control and Automation and Systems and Services | J3: Hosting and Storage and H and S and | K3: Cargo and Clearance | L3: Compressors and Services | M3: Consultancy and Services | O3: Flowline and Construction | P3: Calibration | Q3: Cementing and Stimulation
D4: Geoscience | E4: Earthmoving and Work | F4: Electrical and Engineering and Services | G4: Field and Surface and Geology | H4: Health and Services | I4: Control and Room and System | J4: IT and Hardware and Maintenance | K4: Cargo and Clearance and Services | L4: Engine and Services | M4: Education and Training and Services | O4: GRE and Construction | P4: Corrosion and Inspection | Q4: Coiled and Tubing and Services
